[2022-06-13 08:48:45,442] {taskinstance.py:1159} INFO - Dependencies all met for <TaskInstance: a_call_dag.get_data manual__2022-06-13T08:48:36.354867+00:00 [queued]>
[2022-06-13 08:48:45,463] {taskinstance.py:1159} INFO - Dependencies all met for <TaskInstance: a_call_dag.get_data manual__2022-06-13T08:48:36.354867+00:00 [queued]>
[2022-06-13 08:48:45,465] {taskinstance.py:1356} INFO - 
--------------------------------------------------------------------------------
[2022-06-13 08:48:45,466] {taskinstance.py:1357} INFO - Starting attempt 1 of 1
[2022-06-13 08:48:45,467] {taskinstance.py:1358} INFO - 
--------------------------------------------------------------------------------
[2022-06-13 08:48:45,514] {taskinstance.py:1377} INFO - Executing <Task(PythonOperator): get_data> on 2022-06-13 08:48:36.354867+00:00
[2022-06-13 08:48:45,524] {standard_task_runner.py:52} INFO - Started process 14504 to run task
[2022-06-13 08:48:45,539] {standard_task_runner.py:79} INFO - Running: ['***', 'tasks', 'run', 'a_call_dag', 'get_data', 'manual__2022-06-13T08:48:36.354867+00:00', '--job-id', '28', '--raw', '--subdir', 'DAGS_FOLDER/call_dag.py', '--cfg-path', '/tmp/tmplr6763jm', '--error-file', '/tmp/tmp_mpwdjpy']
[2022-06-13 08:48:45,541] {standard_task_runner.py:80} INFO - Job 28: Subtask get_data
[2022-06-13 08:48:45,702] {task_command.py:370} INFO - Running <TaskInstance: a_call_dag.get_data manual__2022-06-13T08:48:36.354867+00:00 [running]> on host 8ef6f3d8e77e
[2022-06-13 08:48:45,950] {taskinstance.py:1571} INFO - Exporting the following env vars:
AIRFLOW_CTX_DAG_OWNER=***
AIRFLOW_CTX_DAG_ID=a_call_dag
AIRFLOW_CTX_TASK_ID=get_data
AIRFLOW_CTX_EXECUTION_DATE=2022-06-13T08:48:36.354867+00:00
AIRFLOW_CTX_TRY_NUMBER=1
AIRFLOW_CTX_DAG_RUN_ID=manual__2022-06-13T08:48:36.354867+00:00
[2022-06-13 08:48:45,958] {taskinstance.py:1889} ERROR - Task failed with exception
Traceback (most recent call last):
  File "/home/airflow/.local/lib/python3.7/site-packages/airflow/operators/python.py", line 171, in execute
    return_value = self.execute_callable()
  File "/home/airflow/.local/lib/python3.7/site-packages/airflow/operators/python.py", line 189, in execute_callable
    return self.python_callable(*self.op_args, **self.op_kwargs)
  File "/opt/airflow/dags/call_dag.py", line 47, in _read_file
    with open(f'data/{FILE_NAME}.json') as f:
FileNotFoundError: [Errno 2] No such file or directory: 'data/source_list.json.json'
[2022-06-13 08:48:45,998] {taskinstance.py:1400} INFO - Marking task as FAILED. dag_id=a_call_dag, task_id=get_data, execution_date=20220613T084836, start_date=20220613T084845, end_date=20220613T084845
[2022-06-13 08:48:46,047] {standard_task_runner.py:97} ERROR - Failed to execute job 28 for task get_data ([Errno 2] No such file or directory: 'data/source_list.json.json'; 14504)
[2022-06-13 08:48:46,103] {local_task_job.py:156} INFO - Task exited with return code 1
[2022-06-13 08:48:46,287] {local_task_job.py:273} INFO - 0 downstream tasks scheduled from follow-on schedule check
