[2022-06-13 09:32:19,772] {taskinstance.py:1159} INFO - Dependencies all met for <TaskInstance: a_call_dag.get_data manual__2022-06-13T09:32:16.720338+00:00 [queued]>
[2022-06-13 09:32:19,807] {taskinstance.py:1159} INFO - Dependencies all met for <TaskInstance: a_call_dag.get_data manual__2022-06-13T09:32:16.720338+00:00 [queued]>
[2022-06-13 09:32:19,807] {taskinstance.py:1356} INFO - 
--------------------------------------------------------------------------------
[2022-06-13 09:32:19,808] {taskinstance.py:1357} INFO - Starting attempt 1 of 1
[2022-06-13 09:32:19,814] {taskinstance.py:1358} INFO - 
--------------------------------------------------------------------------------
[2022-06-13 09:32:19,896] {taskinstance.py:1377} INFO - Executing <Task(PythonOperator): get_data> on 2022-06-13 09:32:16.720338+00:00
[2022-06-13 09:32:19,933] {standard_task_runner.py:52} INFO - Started process 16337 to run task
[2022-06-13 09:32:19,962] {standard_task_runner.py:79} INFO - Running: ['***', 'tasks', 'run', 'a_call_dag', 'get_data', 'manual__2022-06-13T09:32:16.720338+00:00', '--job-id', '33', '--raw', '--subdir', 'DAGS_FOLDER/call_dag.py', '--cfg-path', '/tmp/tmpgzuebz65', '--error-file', '/tmp/tmp_am5ql1k']
[2022-06-13 09:32:19,964] {standard_task_runner.py:80} INFO - Job 33: Subtask get_data
[2022-06-13 09:32:20,167] {task_command.py:370} INFO - Running <TaskInstance: a_call_dag.get_data manual__2022-06-13T09:32:16.720338+00:00 [running]> on host 8ef6f3d8e77e
[2022-06-13 09:32:20,562] {taskinstance.py:1571} INFO - Exporting the following env vars:
AIRFLOW_CTX_DAG_OWNER=***
AIRFLOW_CTX_DAG_ID=a_call_dag
AIRFLOW_CTX_TASK_ID=get_data
AIRFLOW_CTX_EXECUTION_DATE=2022-06-13T09:32:16.720338+00:00
AIRFLOW_CTX_TRY_NUMBER=1
AIRFLOW_CTX_DAG_RUN_ID=manual__2022-06-13T09:32:16.720338+00:00
[2022-06-13 09:32:21,700] {taskinstance.py:1889} ERROR - Task failed with exception
Traceback (most recent call last):
  File "/home/airflow/.local/lib/python3.7/site-packages/airflow/operators/python.py", line 171, in execute
    return_value = self.execute_callable()
  File "/home/airflow/.local/lib/python3.7/site-packages/airflow/operators/python.py", line 189, in execute_callable
    return self.python_callable(*self.op_args, **self.op_kwargs)
  File "/opt/airflow/dags/call_dag.py", line 61, in _read_table
    data = json.loads(source_str)
  File "/usr/local/lib/python3.7/json/__init__.py", line 348, in loads
    return _default_decoder.decode(s)
  File "/usr/local/lib/python3.7/json/decoder.py", line 337, in decode
    obj, end = self.raw_decode(s, idx=_w(s, 0).end())
  File "/usr/local/lib/python3.7/json/decoder.py", line 353, in raw_decode
    obj, end = self.scan_once(s, idx)
json.decoder.JSONDecodeError: Expecting property name enclosed in double quotes: line 1 column 2 (char 1)
[2022-06-13 09:32:21,731] {taskinstance.py:1400} INFO - Marking task as FAILED. dag_id=a_call_dag, task_id=get_data, execution_date=20220613T093216, start_date=20220613T093219, end_date=20220613T093221
[2022-06-13 09:32:21,766] {standard_task_runner.py:97} ERROR - Failed to execute job 33 for task get_data (Expecting property name enclosed in double quotes: line 1 column 2 (char 1); 16337)
[2022-06-13 09:32:21,814] {local_task_job.py:156} INFO - Task exited with return code 1
[2022-06-13 09:32:21,982] {local_task_job.py:273} INFO - 0 downstream tasks scheduled from follow-on schedule check
