[2022-06-13 08:57:53,607] {taskinstance.py:1159} INFO - Dependencies all met for <TaskInstance: a_call_dag.get_data manual__2022-06-13T08:57:45.536963+00:00 [queued]>
[2022-06-13 08:57:53,629] {taskinstance.py:1159} INFO - Dependencies all met for <TaskInstance: a_call_dag.get_data manual__2022-06-13T08:57:45.536963+00:00 [queued]>
[2022-06-13 08:57:53,629] {taskinstance.py:1356} INFO - 
--------------------------------------------------------------------------------
[2022-06-13 08:57:53,629] {taskinstance.py:1357} INFO - Starting attempt 1 of 1
[2022-06-13 08:57:53,630] {taskinstance.py:1358} INFO - 
--------------------------------------------------------------------------------
[2022-06-13 08:57:53,652] {taskinstance.py:1377} INFO - Executing <Task(PythonOperator): get_data> on 2022-06-13 08:57:45.536963+00:00
[2022-06-13 08:57:53,658] {standard_task_runner.py:52} INFO - Started process 14897 to run task
[2022-06-13 08:57:53,662] {standard_task_runner.py:79} INFO - Running: ['***', 'tasks', 'run', 'a_call_dag', 'get_data', 'manual__2022-06-13T08:57:45.536963+00:00', '--job-id', '30', '--raw', '--subdir', 'DAGS_FOLDER/call_dag.py', '--cfg-path', '/tmp/tmp9km0lqln', '--error-file', '/tmp/tmp9c29v3ob']
[2022-06-13 08:57:53,663] {standard_task_runner.py:80} INFO - Job 30: Subtask get_data
[2022-06-13 08:57:53,734] {task_command.py:370} INFO - Running <TaskInstance: a_call_dag.get_data manual__2022-06-13T08:57:45.536963+00:00 [running]> on host 8ef6f3d8e77e
[2022-06-13 08:57:53,840] {taskinstance.py:1571} INFO - Exporting the following env vars:
AIRFLOW_CTX_DAG_OWNER=***
AIRFLOW_CTX_DAG_ID=a_call_dag
AIRFLOW_CTX_TASK_ID=get_data
AIRFLOW_CTX_EXECUTION_DATE=2022-06-13T08:57:45.536963+00:00
AIRFLOW_CTX_TRY_NUMBER=1
AIRFLOW_CTX_DAG_RUN_ID=manual__2022-06-13T08:57:45.536963+00:00
[2022-06-13 08:57:53,842] {taskinstance.py:1889} ERROR - Task failed with exception
Traceback (most recent call last):
  File "/home/airflow/.local/lib/python3.7/site-packages/airflow/operators/python.py", line 171, in execute
    return_value = self.execute_callable()
  File "/home/airflow/.local/lib/python3.7/site-packages/airflow/operators/python.py", line 189, in execute_callable
    return self.python_callable(*self.op_args, **self.op_kwargs)
  File "/opt/airflow/dags/call_dag.py", line 47, in _read_file
    with open(f'{GCS_URL}') as f:
FileNotFoundError: [Errno 2] No such file or directory: 'gs://wwxt202204/data/source_list.json'
[2022-06-13 08:57:53,858] {taskinstance.py:1400} INFO - Marking task as FAILED. dag_id=a_call_dag, task_id=get_data, execution_date=20220613T085745, start_date=20220613T085753, end_date=20220613T085753
[2022-06-13 08:57:53,883] {standard_task_runner.py:97} ERROR - Failed to execute job 30 for task get_data ([Errno 2] No such file or directory: 'gs://wwxt202204/data/source_list.json'; 14897)
[2022-06-13 08:57:53,918] {local_task_job.py:156} INFO - Task exited with return code 1
[2022-06-13 08:57:54,005] {local_task_job.py:273} INFO - 0 downstream tasks scheduled from follow-on schedule check
