[2022-06-13 09:14:05,340] {taskinstance.py:1159} INFO - Dependencies all met for <TaskInstance: a_call_dag.preparation_task manual__2022-06-13T09:13:58.148290+00:00 [queued]>
[2022-06-13 09:14:05,356] {taskinstance.py:1159} INFO - Dependencies all met for <TaskInstance: a_call_dag.preparation_task manual__2022-06-13T09:13:58.148290+00:00 [queued]>
[2022-06-13 09:14:05,357] {taskinstance.py:1356} INFO - 
--------------------------------------------------------------------------------
[2022-06-13 09:14:05,357] {taskinstance.py:1357} INFO - Starting attempt 1 of 1
[2022-06-13 09:14:05,358] {taskinstance.py:1358} INFO - 
--------------------------------------------------------------------------------
[2022-06-13 09:14:05,380] {taskinstance.py:1377} INFO - Executing <Task(PythonOperator): preparation_task> on 2022-06-13 09:13:58.148290+00:00
[2022-06-13 09:14:05,389] {standard_task_runner.py:52} INFO - Started process 15563 to run task
[2022-06-13 09:14:05,393] {standard_task_runner.py:79} INFO - Running: ['***', 'tasks', 'run', 'a_call_dag', 'preparation_task', 'manual__2022-06-13T09:13:58.148290+00:00', '--job-id', '32', '--raw', '--subdir', 'DAGS_FOLDER/call_dag.py', '--cfg-path', '/tmp/tmpysdk05k5', '--error-file', '/tmp/tmp3cpkzfnr']
[2022-06-13 09:14:05,394] {standard_task_runner.py:80} INFO - Job 32: Subtask preparation_task
[2022-06-13 09:14:05,506] {task_command.py:370} INFO - Running <TaskInstance: a_call_dag.preparation_task manual__2022-06-13T09:13:58.148290+00:00 [running]> on host 8ef6f3d8e77e
[2022-06-13 09:14:05,657] {taskinstance.py:1571} INFO - Exporting the following env vars:
AIRFLOW_CTX_DAG_OWNER=***
AIRFLOW_CTX_DAG_ID=a_call_dag
AIRFLOW_CTX_TASK_ID=preparation_task
AIRFLOW_CTX_EXECUTION_DATE=2022-06-13T09:13:58.148290+00:00
AIRFLOW_CTX_TRY_NUMBER=1
AIRFLOW_CTX_DAG_RUN_ID=manual__2022-06-13T09:13:58.148290+00:00
[2022-06-13 09:14:05,677] {taskinstance.py:1889} ERROR - Task failed with exception
Traceback (most recent call last):
  File "/home/airflow/.local/lib/python3.7/site-packages/airflow/operators/python.py", line 171, in execute
    return_value = self.execute_callable()
  File "/home/airflow/.local/lib/python3.7/site-packages/airflow/operators/python.py", line 189, in execute_callable
    return self.python_callable(*self.op_args, **self.op_kwargs)
  File "/opt/airflow/dags/call_dag.py", line 44, in _process_obtained_data
    value=list_of_sources['source'], serialize_json=True)
TypeError: string indices must be integers
[2022-06-13 09:14:05,693] {taskinstance.py:1400} INFO - Marking task as FAILED. dag_id=a_call_dag, task_id=preparation_task, execution_date=20220613T091358, start_date=20220613T091405, end_date=20220613T091405
[2022-06-13 09:14:05,735] {standard_task_runner.py:97} ERROR - Failed to execute job 32 for task preparation_task (string indices must be integers; 15563)
[2022-06-13 09:14:05,771] {local_task_job.py:156} INFO - Task exited with return code 1
[2022-06-13 09:14:05,901] {local_task_job.py:273} INFO - 0 downstream tasks scheduled from follow-on schedule check
